<!-- Go2 simplified model: NO mesh files, collision-only geometry.
     Identical physics to go2.xml but safe to load in mujoco_wasm without OBJ assets. -->
<mujoco model="go2_simple">
  <compiler angle="radian" autolimits="true" />

  <option cone="elliptic" impratio="100" />

  <default>
    <default class="go2">
      <geom friction="0.4" margin="0.001" condim="1"/>
      <joint axis="0 1 0" damping="0.1" armature="0.01" frictionloss="0.2"/>
      <motor ctrlrange="-23.7 23.7"/>
      <default class="abduction">
        <joint axis="1 0 0" range="-1.0472 1.0472"/>
      </default>
      <default class="front_hip">
        <joint range="-1.5708 3.4907"/>
      </default>
      <default class="back_hip">
        <joint range="-0.5236 4.5379"/>
      </default>
      <default class="knee">
        <joint range="-2.7227 -0.83776"/>
        <motor ctrlrange="-45.43 45.43"/>
      </default>
      <default class="collision">
        <geom group="3"/>
        <default class="foot">
          <geom size="0.022" pos="-0.002 0 -0.213" priority="1" condim="6"
            friction="0.4 0.02 0.01"/>
        </default>
      </default>
    </default>
  </default>

  <worldbody>
    <body name="base_link" pos="0 0 0.445" childclass="go2">
      <inertial pos="0.021112 0 -0.005366" quat="-0.000543471 0.713435 -0.00173769 0.700719"
        mass="6.921" diaginertia="0.107027 0.0980771 0.0244531" />
      <freejoint />
      <!-- trunk collision geoms -->
      <geom size="0.1881 0.04675 0.057" type="box" class="collision" />
      <geom size="0.05 0.045" pos="0.285 0 0.01" type="cylinder" class="collision" />
      <geom size="0.047" pos="0.293 0 -0.06" class="collision" />
      <site name="imu" pos="-0.02557 0 0.04232" />

      <!-- FL leg -->
      <body name="FL_hip" pos="0.1934 0.0465 0">
        <inertial pos="-0.0054 0.00194 -0.000105" quat="0.497014 0.499245 0.505462 0.498237"
          mass="0.678" diaginertia="0.00088403 0.000596003 0.000479967" />
        <joint name="FL_hip_joint" class="abduction" />
        <geom size="0.046 0.02" pos="0 0.08 0" quat="1 1 0 0" type="cylinder" class="collision" />
        <body name="FL_thigh" pos="0 0.0955 0">
          <inertial pos="-0.00374 -0.0223 -0.0327" quat="0.829533 0.0847635 -0.0200632 0.551623"
            mass="1.152" diaginertia="0.00594973 0.00584149 0.000878787" />
          <joint name="FL_thigh_joint" class="front_hip" />
          <geom size="0.1065 0.01225 0.017" pos="0 0 -0.1065" quat="0.707107 0 0.707107 0"
            type="box" class="collision" />
          <body name="FL_calf" pos="0 0 -0.213">
            <inertial pos="0.00629595 -0.000622121 -0.141417"
              quat="0.710672 0.00154099 -0.00450087 0.703508"
              mass="0.241352" diaginertia="0.0014901 0.00146356 5.31397e-05" />
            <joint name="FL_calf_joint" class="knee" />
            <geom size="0.012 0.06" pos="0.008 0 -0.06" quat="0.994493 0 -0.104807 0"
              type="cylinder" class="collision" />
            <geom size="0.011 0.0325" pos="0.02 0 -0.148" quat="0.999688 0 0.0249974 0"
              type="cylinder" class="collision" />
            <geom name="FL" class="foot" />
            <body name="FL_foot" pos="0 0 -0.213" />
          </body>
        </body>
      </body>

      <!-- FR leg -->
      <body name="FR_hip" pos="0.1934 -0.0465 0">
        <inertial pos="-0.0054 -0.00194 -0.000105" quat="0.498237 0.505462 0.499245 0.497014"
          mass="0.678" diaginertia="0.00088403 0.000596003 0.000479967" />
        <joint name="FR_hip_joint" class="abduction" />
        <geom size="0.046 0.02" pos="0 -0.08 0" quat="0.707107 0.707107 0 0" type="cylinder"
          class="collision" />
        <body name="FR_thigh" pos="0 -0.0955 0">
          <inertial pos="-0.00374 0.0223 -0.0327" quat="0.551623 -0.0200632 0.0847635 0.829533"
            mass="1.152" diaginertia="0.00594973 0.00584149 0.000878787" />
          <joint name="FR_thigh_joint" class="front_hip" />
          <geom size="0.1065 0.01225 0.017" pos="0 0 -0.1065" quat="0.707107 0 0.707107 0"
            type="box" class="collision" />
          <body name="FR_calf" pos="0 0 -0.213">
            <inertial pos="0.00629595 0.000622121 -0.141417"
              quat="0.703508 -0.00450087 0.00154099 0.710672"
              mass="0.241352" diaginertia="0.0014901 0.00146356 5.31397e-05" />
            <joint name="FR_calf_joint" class="knee" />
            <geom size="0.013 0.06" pos="0.01 0 -0.06" quat="0.995004 0 -0.0998334 0"
              type="cylinder" class="collision" />
            <geom size="0.011 0.0325" pos="0.02 0 -0.148" quat="0.999688 0 0.0249974 0"
              type="cylinder" class="collision" />
            <geom name="FR" class="foot" />
            <body name="FR_foot" pos="0 0 -0.213" />
          </body>
        </body>
      </body>

      <!-- RL leg -->
      <body name="RL_hip" pos="-0.1934 0.0465 0">
        <inertial pos="0.0054 0.00194 -0.000105" quat="0.505462 0.498237 0.497014 0.499245"
          mass="0.678" diaginertia="0.00088403 0.000596003 0.000479967" />
        <joint name="RL_hip_joint" class="abduction" />
        <geom size="0.046 0.02" pos="0 0.08 0" quat="0.707107 0.707107 0 0" type="cylinder"
          class="collision" />
        <body name="RL_thigh" pos="0 0.0955 0">
          <inertial pos="-0.00374 -0.0223 -0.0327" quat="0.829533 0.0847635 -0.0200632 0.551623"
            mass="1.152" diaginertia="0.00594973 0.00584149 0.000878787" />
          <joint name="RL_thigh_joint" class="back_hip" />
          <geom size="0.1065 0.01225 0.017" pos="0 0 -0.1065" quat="0.707107 0 0.707107 0"
            type="box" class="collision" />
          <body name="RL_calf" pos="0 0 -0.213">
            <inertial pos="0.00629595 -0.000622121 -0.141417"
              quat="0.710672 0.00154099 -0.00450087 0.703508"
              mass="0.241352" diaginertia="0.0014901 0.00146356 5.31397e-05" />
            <joint name="RL_calf_joint" class="knee" />
            <geom size="0.013 0.06" pos="0.01 0 -0.06" quat="0.995004 0 -0.0998334 0"
              type="cylinder" class="collision" />
            <geom size="0.011 0.0325" pos="0.02 0 -0.148" quat="0.999688 0 0.0249974 0"
              type="cylinder" class="collision" />
            <geom name="RL" class="foot" />
            <body name="RL_foot" pos="0 0 -0.213" />
          </body>
        </body>
      </body>

      <!-- RR leg -->
      <body name="RR_hip" pos="-0.1934 -0.0465 0">
        <inertial pos="0.0054 -0.00194 -0.000105" quat="0.499245 0.497014 0.498237 0.505462"
          mass="0.678" diaginertia="0.00088403 0.000596003 0.000479967" />
        <joint name="RR_hip_joint" class="abduction" />
        <geom size="0.046 0.02" pos="0 -0.08 0" quat="0.707107 0.707107 0 0" type="cylinder"
          class="collision" />
        <body name="RR_thigh" pos="0 -0.0955 0">
          <inertial pos="-0.00374 0.0223 -0.0327" quat="0.551623 -0.0200632 0.0847635 0.829533"
            mass="1.152" diaginertia="0.00594973 0.00584149 0.000878787" />
          <joint name="RR_thigh_joint" class="back_hip" />
          <geom size="0.1065 0.01225 0.017" pos="0 0 -0.1065" quat="0.707107 0 0.707107 0"
            type="box" class="collision" />
          <body name="RR_calf" pos="0 0 -0.213">
            <inertial pos="0.00629595 0.000622121 -0.141417"
              quat="0.703508 -0.00450087 0.00154099 0.710672"
              mass="0.241352" diaginertia="0.0014901 0.00146356 5.31397e-05" />
            <joint name="RR_calf_joint" class="knee" />
            <geom size="0.013 0.06" pos="0.01 0 -0.06" quat="0.995004 0 -0.0998334 0"
              type="cylinder" class="collision" />
            <geom size="0.011 0.0325" pos="0.02 0 -0.148" quat="0.999688 0 0.0249974 0"
              type="cylinder" class="collision" />
            <geom name="RR" class="foot" />
            <body name="RR_foot" pos="0 0 -0.213" />
          </body>
        </body>
      </body>

    </body>
  </worldbody>

  <actuator>
    <motor class="abduction" name="FR_hip"   joint="FR_hip_joint" />
    <motor class="front_hip" name="FR_thigh" joint="FR_thigh_joint" />
    <motor class="knee"      name="FR_calf"  joint="FR_calf_joint" />
    <motor class="abduction" name="FL_hip"   joint="FL_hip_joint" />
    <motor class="front_hip" name="FL_thigh" joint="FL_thigh_joint" />
    <motor class="knee"      name="FL_calf"  joint="FL_calf_joint" />
    <motor class="abduction" name="RR_hip"   joint="RR_hip_joint" />
    <motor class="back_hip"  name="RR_thigh" joint="RR_thigh_joint" />
    <motor class="knee"      name="RR_calf"  joint="RR_calf_joint" />
    <motor class="abduction" name="RL_hip"   joint="RL_hip_joint" />
    <motor class="back_hip"  name="RL_thigh" joint="RL_thigh_joint" />
    <motor class="knee"      name="RL_calf"  joint="RL_calf_joint" />
  </actuator>

  <!-- keyframe はこのファイルを include する親 XML 側で定義する
       （nq が include 先で変わるため、ここには書かない） -->
</mujoco>
